
Traceback (most recent call last):
  File "/home/robert/.local/lib/python3.10/site-packages/pyp2p/net.py", line 512, in bootstrap
    rendezvous_con = self.rendezvous.server_connect()
  File "/home/robert/.local/lib/python3.10/site-packages/pyp2p/rendezvous_client.py", line 92, in server_connect
    con.connect(server["addr"], server["port"])
  File "/home/robert/.local/lib/python3.10/site-packages/pyp2p/sock.py", line 188, in connect
    src_ip = get_lan_ip(self.interface)
  File "/home/robert/.local/lib/python3.10/site-packages/pyp2p/lib.py", line 213, in get_lan_ip
    return ip.routes["8.8.8.8"]["prefsrc"]
  File "/home/robert/.local/lib/python3.10/site-packages/pyroute2/ipdb/routes.py", line 1311, in __getitem__
    return self.get(key)
  File "/home/robert/.local/lib/python3.10/site-packages/pyroute2/ipdb/routes.py", line 1295, in get
    return self.tables[table][dst]
  File "/home/robert/.local/lib/python3.10/site-packages/pyroute2/ipdb/routes.py", line 1029, in __getitem__
    return self.describe(key, forward=False)['route']
  File "/home/robert/.local/lib/python3.10/site-packages/pyroute2/ipdb/routes.py", line 968, in describe
    raise KeyError('record not found')
KeyError: 'record not found'
 <class 'KeyError'> net.py 512 'record not found'